{"afters": [{"status": "broken", "start": 1603177197600, "statusDetails": {"trace": "  File \"d:\\work\\tools3\\python\\python35\\lib\\site-packages\\allure_commons\\_allure.py\", line 185, in __call__\n    return self._fixture_function(*args, **kwargs)\n  File \"d:\\work\\tools3\\python\\python35\\lib\\site-packages\\_pytest\\fixtures.py\", line 932, in _teardown_yield_fixture\n    next(it)\n  File \"d:\\work\\tools3\\python\\python35\\lib\\site-packages\\_pytest\\python.py\", line 749, in xunit_setup_class_fixture\n    _call_with_optional_argument(func, self.obj)\n  File \"d:\\work\\tools3\\python\\python35\\lib\\site-packages\\_pytest\\python.py\", line 674, in _call_with_optional_argument\n    func(arg)\n  File \"D:\\tencent-clould\\Test_Console\\test_voyage_service.py\", line 56, in teardown_class\n    commen.init_driver().quit()\n  File \"D:\\tencent-clould\\Commen\\commen.py\", line 21, in init_driver\n    driver.maximize_window()\n  File \"d:\\work\\tools3\\python\\python35\\lib\\site-packages\\selenium\\webdriver\\remote\\webdriver.py\", line 737, in maximize_window\n    self.execute(command, params)\n  File \"d:\\work\\tools3\\python\\python35\\lib\\site-packages\\selenium\\webdriver\\remote\\webdriver.py\", line 319, in execute\n    response = self.command_executor.execute(driver_command, params)\n  File \"d:\\work\\tools3\\python\\python35\\lib\\site-packages\\selenium\\webdriver\\remote\\remote_connection.py\", line 374, in execute\n    return self._request(command_info[0], url, body=data)\n  File \"d:\\work\\tools3\\python\\python35\\lib\\site-packages\\selenium\\webdriver\\remote\\remote_connection.py\", line 397, in _request\n    resp = self._conn.request(method, url, body=body, headers=headers)\n  File \"d:\\work\\tools3\\python\\python35\\lib\\site-packages\\urllib3\\request.py\", line 80, in request\n    method, url, fields=fields, headers=headers, **urlopen_kw\n  File \"d:\\work\\tools3\\python\\python35\\lib\\site-packages\\urllib3\\request.py\", line 171, in request_encode_body\n    return self.urlopen(method, url, **extra_kw)\n  File \"d:\\work\\tools3\\python\\python35\\lib\\site-packages\\urllib3\\poolmanager.py\", line 336, in urlopen\n    response = conn.urlopen(method, u.request_uri, **kw)\n  File \"d:\\work\\tools3\\python\\python35\\lib\\site-packages\\urllib3\\connectionpool.py\", line 765, in urlopen\n    **response_kw\n  File \"d:\\work\\tools3\\python\\python35\\lib\\site-packages\\urllib3\\connectionpool.py\", line 765, in urlopen\n    **response_kw\n  File \"d:\\work\\tools3\\python\\python35\\lib\\site-packages\\urllib3\\connectionpool.py\", line 765, in urlopen\n    **response_kw\n  File \"d:\\work\\tools3\\python\\python35\\lib\\site-packages\\urllib3\\connectionpool.py\", line 725, in urlopen\n    method, url, error=e, _pool=self, _stacktrace=sys.exc_info()[2]\n  File \"d:\\work\\tools3\\python\\python35\\lib\\site-packages\\urllib3\\util\\retry.py\", line 439, in increment\n    raise MaxRetryError(_pool, url, error or ResponseError(cause))\n", "message": "urllib3.exceptions.MaxRetryError: HTTPConnectionPool(host='127.0.0.1', port=62547): Max retries exceeded with url: /session/334902bd-d34b-4943-9f0e-29dd3862c4f4/window/maximize (Caused by NewConnectionError('<urllib3.connection.HTTPConnection object at 0x000001EEBABBDEF0>: Failed to establish a new connection: [WinError 10061] 由于目标计算机积极拒绝，无法连接。',))\n"}, "name": "_Class__pytest_setup_class::0", "stop": 1603177205836}], "uuid": "e9b410ce-7d2c-44e0-8676-f350a3735683", "children": ["8596daec-a027-44b6-b532-07e39a128970"], "stop": 1603177205836, "befores": [{"status": "passed", "start": 1603177189297, "name": "_Class__pytest_setup_class", "stop": 1603177189297}], "start": 1603177189297}